Workbook
Name _Hlk149905875: 'Гидравл. расчет'!$A$22
Name DN_подвод_патрубка: Таблица9[DN подвод патрубка]
Name DN_подвод_патрубка: Таблица9[DN подвод патрубка]
Name Асбестцемент: Таблица9[DN подвод патрубка]
Name Асбестцемент: Таблица9[DN подвод патрубка]
Name Асбестцемент: Таблица9[DN подвод патрубка]
Name Валюта: Таблица72[Валюта]
Name Валюта: Таблица72[Валюта]
Name Группа: Таблица301715[Группа]
Name Давление: Таблица11[Давление]
Name Давление: Таблица11[Давление]
Name Давление: Таблица11[Давление]
Name Давление_для_проч_эл: Таблица44[Давление_для_проч_эл]
Name Давление_для_проч_эл: Таблица44[Давление_для_проч_эл]
Name Давление_для_фланцев: Таблица43[Давление_для_фланцев]
Name Давление_для_фланцев: Таблица43[Давление_для_фланцев]
Name Диаметр: Таблица8[Диаметр]
Name Диаметр: Таблица8[Диаметр]
Name Диаметр: Таблица8[Диаметр]
Name ЕИ: Таблица2[ЕИ]
Name ЕИ: Таблица2[ЕИ]
Name ЕИ: Таблица2[ЕИ]
Name Жесткость: Таблица13[Жесткость]
Name Жесткость: Таблица13[Жесткость]
Name Жесткость: Таблица13[Жесткость]
Name Изделие: Таблица6[Наименование изделия]
Name Изделие: Таблица6[Наименование изделия]
Name Изделие: Таблица6[Наименование изделия]
Name Категории: Списки!$AF$2:$AF$18
Name Категории: Списки!$AF$2:$AF$18
Name Категории: Списки!$AF$2:$AF$18
Name Категории: Списки!$AG$2:$AG$17
Name Материал: Таблица4[Материал]
Name Материал: Таблица4[Материал]
Name Материал: Таблица4[Материал]
Name Материал_трубы: Таблица3[Материал трубы]
Name Метизы: #REF!
Name Отвод: Таблица45[Отвод]
Name Отвод: Таблица45[Отвод]
Name ПВХ: Таблица9[DN подвод патрубка]
Name ПВХ: Таблица9[DN подвод патрубка]
Name ПВХ: Таблица9[DN подвод патрубка]
Name ПНД: Таблица9[DN подвод патрубка]
Name ПНД: Таблица9[DN подвод патрубка]
Name ПНД: Таблица9[DN подвод патрубка]
Name ПП: Таблица9[DN подвод патрубка]
Name ПП: Таблица9[DN подвод патрубка]
Name ПП: Таблица9[DN подвод патрубка]
Name ПЭ: 'Вес трубы, ПЭ трубы'!$U$2:$U$27
Name Среда: Таблица5[Среда]
Name Среда: Таблица5[Среда]
Name Среда: Таблица5[Среда]
Name Тип_емкости: Таблица37[Тип емкости]
Name Тип_емкости: Таблица37[Тип емкости]
Name Тип_ОЛ: Таблица42[Тип_ОЛ]
Name Тип_ОЛ: Таблица42[Тип_ОЛ]
Name Тип_патрубка: Таблица40[Тип патрубка]
Name Тип_патрубка: Таблица40[Тип патрубка]
Name Тройник: Таблица48[Тройник]
Name Тройник: Таблица48[Тройник]

Sheet Инструкции
C1: Инструкции | D1: к содержанию
B3: Что запрещается?
B4: 1. | C4: Изменять названия листов, категорий
B5: 2. | C5: Изменять навзания шапки таблиц во вкладках с Категоряими
B6: 3. | C6: Вставлять в ячейку скопированное из другого файла (можно только через правую кнопку мыши "Вставить значения")
B7: 4. | C7: Менять цвета (если добавляете какие-то цвета в процессе работы, то когда закончите свою раюоту - верните, пожалуйста, исходные цвета
B8: 5. | C8: В наименовании номенклатуры использовать знак "~" (тильда).
B10: Как пользоваться Опросным Листом?
B12: 1. | C12: Заполните поля, выделенные рамкой
B13: 2. | C13: В некоторых полях требуется выбрать из выпадающего списка (например, диаметр, давление, да/нет, и т.д.) в некоторых заполнить произвольным текстом (например, заказчик, объект, комментарии и пр.)
B28: 3. | C28: Распечатайте опросный лист
B30: Как пользоваться Калькулятором?
B32: 1. | C32: Заполняйте ячейки только на белом фоне (они без формул). Ячейки в бежевом цвете НЕ ЗАПОЛНЯТЬ (они содержат формулы).
B52: 2. | C52: В шапке таблицы с вводными данными есть "белые" ячейки, не требующие обязательного заполнения, т.к. значения для расчета уже подставлены автоматически либо по формуле, либо из таблиц, либо из ОЛ. Однако, если требуется иное значение, то в таких случаях предусмотрена возможность ручного ввода. Рядом (слева от значения по умолчанию) стоят "белые" поля, где можете подставить свое значение. Калькулятор будет брать для расчета "ручное" значение. Если в "белом" поле будет пусто, то калькулятор возьмет для расчета уже подставленное значние из "бежевого" поля.
C53: Вставить: форматы.
B69: 3. | C69: В самом калькуляторе многие значения уже подсчитываются по формуле или транслируются из введеных ранее данных или встроенных таблиц, Если же таких автоматически заполненных данных нет, то "открывается" белое окошечко, в которое необходимо подставить значения вручную.
B87: Как заполнять поля?
B89: 1. | C89: Прежде чем выбрать номенклатуру (из выпадающего списка или, если не нашли подходящую, вписать вручную), необходимо выбрать из выпадающего списка категорию номенклатуры
B101: 2. | C101: Заполнить все "белые" ячейки в строке (иногда это количество, цена, иногда ничего заполнять не надо, т.к. все подтянется автоматически, тогда "белых"ячеек не будет)
B102: 3. | C102: В блоке Фальшпол необходимо выбрать ДА/НЕТ (в зависимости от того, что требуется в исходных данных). А вот такие блоки как Теплоизоляция, Корзина, Дробилка - будут атоматически "утопать" белым цветом, что означает "не участвуют в расчете", или будут обычным черным шрифтом, т.е. "участвуют в расчете", в зависимости от того, что выбрано в ОЛ.
B117: Как добавлять/удалять строки
B119: 1. | C119: Выделите ВСЮ строку, НАД которой будете вставлять строку → на верхней панели инструментов вкладка Главная → Вставить
B147: 2. | C147: Выделите любую заполненную строку → Скопируйте (Ctrl+C или правкой кнопкой мыши Копировать) → выделите ВСЮ пустую строку и вставьте то, что скопировали в буфер (Ctrl+V или правой кнопкой мыши Вставить)
C157: Или выбеделите ВСЮ заполненную строку и просто потяните за уголок вниз (или вверх)
B167: 3. | C167: Если необзодимо УДАЛИТЬ, то выделите ВСЮ строку, предназначенную для уделения → на верхней панели инструментов вкладка Главная → Удалить
B170: Как добавлять номенклатуру, цены, скидки и пр. во вкладки Категории
B172: 1. | C172: Важный момент - шапки заголовков и наименования самих вкладов менять НЕЛЬЗЯ.
B174: 2. | C174: Чтобы добавить номенклатуру, необходимо либо вручную внести в пустую строку (формат и формулы подтянуться автоматически) либо скопировать из другого файла, но!!! Через правую кнопку мыши "Вставить значения"
B196: 3. | C196: В графах ЕИ и Валюта выбрать из выпадающего списка необходимую ЕИ и валюту. Или вставить скопированную как описано в п.1. ВНИМАНИЕ! ВСЕ ЕИ и валюта должны быть точно такие же как в выпадающем списке!
B198: 4. | C198: Указать цену, процент скидки. Если необходимо, написать комментарий. Все цены вписывать с НДС.
B200: 5. | C200: Можно исправить курс ЕВРО и ДОЛЛАРА при необходимости
B202: 6. | C202: ячейки с бежевым фоном не исправлять
B205: Как распечатывать лист?
B207: 1. | C207: Откройте Лист, который необходимо распечатать. Проверьте все ли правльно. Можете что-то подредактировать, например, отфильтроввать пустые строки.
B224: 2. | C224: Далее на верхней панеле инструментов Файл → Печать → В разделе Настройки сделать следущие манипуляции:
B226: 2.1. | C226: Если у Вас печать листа, то выбор должен стоять на Напечатать активные листы. Если определенный диапазон (выделить необходимые ячейки), то Напечатать выделенный фрагмент.
B252: 2.2. | C252: Чтобы уместить печать листа на одну страницу необходимо выбрать Вписать лист на одну страницу. В этом случае все, что на листе, будет размещено на одной странице. Посмотрите на образец размещения после печати справа.
C253: Если необзодимо уместить лист только по ширине в пределах одной страницы, а в "длину" можно на нескольких страницах, то выберете Вписать все столбцы на одну страницу. Посмотрите на образоц справа.
B285: 2.3. | C285: Внизу будет показано количество страниц после печати. Если все устраивает,то нажмите Печать.

Sheet Содержание
C1: Содержание | E1: =MID(CELL("имяфайла"),SEARCH("[",CELL("имяфайла"))+1,SEARCH("]",CELL("имяфайла"))-SEARCH("[",CELL("имяфайла"))-1) -> Шаблон 3.0.xlsx
C3: Выберите тип опросного листа | D3: ОЛ емкости | E3: =IF(D3=Списки!BB2,HYPERLINK("["&E1&"]ОЛ_Емкости!A1","Нажмите ссылку, чтобы перейти на ОЛ"),HYPERLINK("["&E1&"]ОЛ_НАСОСНАЯ_СТАНЦИЯ!A1","Нажмите ссылку, чтобы перейти на ОЛ")) -> Нажмите ссылку, чтобы перейти на ОЛ
B6: № | C6: Содержание | D6: Описание
B7: 1 | C7: Инструкции
B8: 2 | C8: Опросный лист
B9: 3 | C9: Калькулятор
B10: 4 | C10: Заявка на закупку
B11: 5 | C11: Днище КНС
B12: 6 | C12: Вес и ПЭ трубы
B13: 7 | C13: Грузоподъем
B14: 8 | C14: Детали трубопровода ПЭ ПВХ PP
B15: 9 | C15: Детали трубопровода сталь
B16: 10 | C16: Запорная арматура
B17: 11 | C17: Металлопрокат
B18: 12 | C18: Метизы
... B23: 17 | C23: Работы

Sheet Списки
A1: Выбор | B1: Стадия | C1: Шкаф управления | D1: Ввод электропитания | E1: Пуск ШУ | F1: Модуль передачи данных в систему диспетчеризации: | G1: Вид насосной станции | H1: Корзина или Дробилка | I1: Тип запорной арматуры | L1: Материал трубы | M1: Тип соединения | P1: Наименование изделия | Q1: Материал | R1: Среда | S1: ЕИ | U1: ЕИ для ОЛ | W1: Валюта | Y1: DN подвод патрубка | Z1: Диаметр | AB1: Давление | AC1: Давление_для_фланцев | AD1: Давление_для_проч_эл | AE1: Жесткость | AG1: Категории | AI1: Труба на части | AK1: Расположение | AM1: Установка | AO1: Тип емкости | AQ1: Д шахты обслуживания | AS1: Класс опасности | AU1: Тип патрубка | AW1: Тип крышки | AY1: Отвод | AZ1: Тройник | BA1: Фланец | BB1: Тип_ОЛ | BC1: Тип емкости | BD1: Вид днища | BF1: Назначение ОЛ | BH1: Тип смолы | BI1: Марка смолы | BJ1: Отдел | BM1: Диапозон давления | BN1: Предполагаемый тип соединения подводящего трубопровода с КНС | BO1: Напорный трубопровод DN150 1+1 | BP1: 1 | BQ1: 1+1
A2: Да | B2: проект | C2: Внутренний | D2: Один | E2: Стандартный | F2: CIM 150 Profibus-DR | G2: КНС | H2: Корзина для мусора | I2: Задвижка клиновая с обрезиненным клином | L2: ПЭ | M2: фланец | P2: Труба | Q2: СК/НПС | R2: К | S2: шт | U2: л/с | W2: руб | Y2: 50 | Z2: 300 | AB2: 0.1 | AC2: 0,1-0,6 | AD2: 0,1-0,4 | AE2: 1250 | AG2: Грузоподъем | AI2: Целая труба | AK2: Горизонтальное | AM2: Наземная | AO2: Накопительная | AQ2: 700 | AS2: I | AU2: Раструб | AW2: Крышка из нерж. стали | AY2: Отвод с углом изгиба от 0 до 30. 15 град | AZ2: Тройник равнопроходной | BA2: Формованный фланец под ламинарное/муфтовое соединение | BB2: ОЛ емкости | BC2: Типовая | BD2: С патрубком | BF2: Материальный расчет | BH2: Стандарт | BI2: ИЗО | BJ2: Дирекция по продажам (Направление продаж трубной продукции) | BM2: 0...0,1 | BP2: 2 | BQ2: 2+1
A3: Нет | B3: рабочая | C3: Уличный | D3: Двойной с АВР | E3: Плавный | F3: CIM 200Modbus RTU/COMLI | G3: ДНС | H3: Дробилка | I3: Задвижка шиберная | L3: ПВХ | M3: муфта | P3: Муфта | Q3: СК/ВЭС | S3: м | U3: м3/ч | W3: евро | Y3: 65 | Z3: 400 | AB3: 0.4 | AC3: 0,6-1,0 | AD3: 0.6 | AE3: 2500 | AG3: Выключатели | AI3: Труба частями | AK3: Вертикальное | AM3: Подземная | AO3: Химстойкая | AQ3: 800 | AS3: II | AU3: Формованный стеклокомпозитный фланец | AW3: Крышка стеклокомпозитная | AY3: Отвод с углом изгиба от 0 до 30. 30 град | BA3: Металлический фланец на формованном упоре | BB3: ОЛ насосной станции | BC3: Сборная | BD3: Без патрубка | BF3: Расчет на всплытие | BH3: Винилэфирная стандарт | BI3: Девинил911 | BJ3: Дирекция по продажам (Направление проектных продаж) | BM3: 0...0,16 | BQ3: нестандартное
B4: кд | E4: Частотный преобразователь | F4: CIM 250 GSM/GPRS | G4: ВНС | H4: Корзина для мусора и Дробилка | I4: Задвижка шиберная с электроприводом | L4: ПНД | M4: раструб | P4: Фасонные детали | S4: кг | U4: м3/сут | W4: долл | Y4: 80 | Z4: 500 | AB4: 0.6 | AC4: 1,0-1,6 | AD4: 1 | AE4: 5000 | AG4: Детали труб_да ПЭ ПВХ PPR | AM4: В помещении | AO4: Аккумулирующая | AQ4: 900 | AS4: III | AU4: Металлический фланец на формованном упоре | AY4: Отвод с углом изгиба от 31 до 60. 45 град | BB4: ОЛ колодца | BF4: Расчет кольцевой жесткости (толщины стенки корпуса) | BH4: Винилэфирная высокотемпературная (до 180°С) | BI4: Derakan470 | BJ4: Дирекция инжиниринга и проектных работ (Проектно-конструкторский отдел) | BM4: 0...0,25
A5: Отправить на подбор смолы | B5: продажа | H5: нет | I5: Задвижка клиновая с обрезиненным клином с электроприводом | L5: ПП | S5: чел. ч | Y5: 100 | Z5: 600 | AB5: 1 | AC5: 1,6-2,0 | AD5: 1.6 | AE5: 10000 | AG5: Детали трубопровода сталь | AM5: Автомобиль | AO5: Питьевая | AQ5: 1000 | AS5: IV | AU5: Фланцевый патрубок с заглушкой | AY5: Отвод с углом изгиба от 31 до 60. 60 град | BF5: Согласовательный чертеж | BJ5: Дирекция инжиниринга и проектных работ (Опытно-технологический отдел) | BM5: 0...0,4
B6: тендер | L6: Асбестцемент | S6: м² | Y6: 150 | Z6: 700 | AB6: 1.6 | AD6: 2 | AG6: Запорная арматура | AO6: Емкость с насосным оборудованием | AQ6: 1100 | AU6: Фланцевый патрубок | AY6: Отвод с углом изгиба от 61 до 90. 75 град | BJ6: Дирекция инжиниринга и проектных работ (Конструкторско-технологический отдел) | BM6: 0...0,6
A7: 6 | L7: Труба Корсис | S7: руб/м | Y7: 200 | Z7: 800 | AB7: 2 | AG7: Металлопрокат | AQ7: 1200 | AY7: Отвод с углом изгиба от 61 до 90. 90 град | BJ7: Дирекция по развитию (Отдел продаж емкостного оборудования) | BM7: 0…1
A8: 12 | L8: Труба стеклокомпозитная | Y8: 250 | Z8: 900 | AB8: 2.5 | AG8: Метизы | AQ8: 1300 | BJ8: Департамент по закупкам и логистике | BM8: 0…1,6
Y9: 300 | Z9: 1000 | AB9: 3.2 | AG9: Прочее оборудование | AQ9: 1400 | BM9: 0…2,5
Y10: 350 | Z10: 1100 | AG10: Насосы, АТМ | AQ10: 3000 | BM10: 0…4
E11: =IF(ISBLANK(B11),"",IF(OR(B11=Списки!AG15:AG17),"нет","да")) | Y11: 400 | Z11: 1200 | AG11: Датчики | BM11: 0…6
Y12: 450 | Z12: 1300 | AG12: Расходомеры | BM12: 0…10
Y13: 500 | Z13: 1400 | AG13: Шкафы
Y14: 550 | Z14: 1500 | AG14: Прочие материалы
Y15: 600 | Z15: 1600 | AG15: Собственное производство
Y16: 650 | Z16: 1700 | AG16: Работы
Y17: 700 | Z17: 1800 | AG17: ФОТ
Y18: 750 | Z18: 1900
Y19: 800 | Z19: 2000
Y20: 850 | Z20: 2100
Y21: 900 | Z21: 2200
Y22: 950 | Z22: 2300
Y23: 1000 | Z23: 2400
Y24: 1100 | Z24: 2500
Y25: 1200 | Z25: 2600
Y26: 1300 | Z26: 2700
Y27: 1400 | Z27: 2800
Y28: 1500 | Z28: 2900
Y29: 1600 | Z29: 3000
Z30: 3200
Z31: 3600

Sheet Инструкции1
C1: Инструкции | D1: к содержанию
B3: Что запрещается?
B4: 1. | C4: Изменять названия листов, категорий
B5: 2. | C5: Изменять навзания шапки таблиц во вкладках с Категоряими
B6: 3. | C6: Вставлять в ячейку скопированное из другого файла (можно только через правую кнопку мыши "Вставить значения")
B7: 4. | C7: Менять цвета (если добавляете какие-то цвета в процессе работы, то когда закончите свою раюоту - верните, пожалуйста, исходные цвета
B8: 5. | C8: В наименовании номенклатуры использовать знак "~" (тильда).
B10: Как пользоваться Опросным Листом для КНС?
B12: 1. | C12: Заполните ячейки с общей информацией по задача/объекту
D19: Номер ОЛ вводится вручную
D20: Тип станции можно выбрать из списка
B28: 2.1. | C28: Согласно поставленной задаче выбирается диаметр корпуса и жесткость. Диаметр должен быть согласован с менеджерами (труба со склада или из конкретного выпуска)
D35: Глубина корпуса (подземная часть) расчитывается отдельно рядом с основным полем ОЛ. Если подобранная глубина корпуса не соответствует исходным данным, можно поставить длину вручную
D36: Обязательно для заполнения вкладка по ТТ МВК Да/Нет, т.к. много блоков учтены именно для МВК
B37: 2.2. | C37: Заполняются исходные данные (если таковые имеются): диаметры входных и выходных патрубков, их глубины, количество, материал
D40: Все ячейки из данного блока обязательны к заполнению для разработки мат. расчета.
B54: 2.3. | C54: Основные параметры КНС: расход и расчетный напор для подбора насосного оборудования и габаритов корпуса
D57: Производительность КНС лучше всегда указывать в м3/ч, т.к. подбор габаритов корпуса рассчитывается в м3/ч. Производительность вводится вручную
B64: 2.4. | C64: Подбор корпуса происходит рядом с основным листом КНС. Подбор корпуса зависит от высоты полезного объема, мин. уровня жидкости в КНС. В этой таблице вручную заполняется только уровень из тех. паспорта насоса, высота рамы насосов, остальные параметра - расчетные
D67: Согласно ТЗ (или поставленной задаче) выбирается количество пусков насосов в час: 5,10,20 пусков в час, 5-10-20 минутная работа насосов)
D73: Мин.уровень жидкости для работы насоса указан в тех.паспорте подобранного насоса
D74: Например: уровень C.W.L.
B86: 2.5. | C86: После предварительного подбора корпуса заполняются данные о шкафах управления (если таковые имеются), наличии датчиков, доп. Оборудования и теплоизоляции
B97: Как пользоваться Калькулятором?
C99: Заполняйте ячейки только на белом фоне (они без формул). Ячейки в бежевом цвете НЕ ЗАПОЛНЯТЬ (они содержат формулы).
C117: Если нужно посчитать не по формуле, а поставить конкретное число, то для этого по всему калькулятору есть столбец Н. То есть в любой строчке расчета можно поставить значение вручную,
B132: Как заполнять поля?
C134: Прежде чем выбрать номенклатуру (из выпадающего списка или, если не нашли подходящую, вписать вручную), необходимо выбрать из выпадающего списка категорию номенклатуры. То есть в каждой категории своя номенклатура.
D136: Вручную можно заполнить наименование оборудования, труб, металлопрокатов, если необходимой позиции нет в выпадающем списке
D141: Согласно выбранной категории подтягивается перечень позиций, и нужная выбирается. Если нужно ввести вручную всегда значения ставятся в столбец Н, если не нужно, все подтягивается автоматически
C150: Если позиция была введена вручную (не из списка номенклатуры), то и стоимость этой позиции нужно будет ввести вручную (это будет столбец L)
B170: Как добавлять/удалять строки
B172: 1. | C172: Выделите любую заполненную строку → Скопируйте (Ctrl+C или правкой кнопкой мыши Копировать) → выделите ВСЮ пустую строку и вставьте то, что скопировали в буфер (Ctrl+V или правой кнопкой мыши Вставить)
C179: Или выбеделите ВСЮ заполненную строку и просто потяните за уголок вниз (или вверх)
B190: 3. | C190: Если необзодимо УДАЛИТЬ, то выделите ВСЮ строку, предназначенную для уделения → на верхней панели инструментов вкладка Главная → Удалить
B193: Как добавлять номенклатуру, цены, скидки и пр. во вкладки Категории
B195: 1. | C195: Важный момент - шапки заголовков и наименования самих вкладок менять НЕЛЬЗЯ.
B197: 2. | C197: Чтобы добавить номенклатуру, необходимо либо вручную внести в пустую строку (формат и формулы подтянуться автоматически) либо скопировать из другого файла, но!!! Через правую кнопку мыши "Вставить значения"
B217: 3. | C217: В графах ЕИ и Валюта выбрать из выпадающего списка необходимую ЕИ и валюту. Или вставить скопированную как описано в п.1. ВНИМАНИЕ! ВСЕ ЕИ и валюта должны быть точно такие же как в выпадающем списке!
B219: 4. | C219: Указать цену, процент скидки. Если необходимо, написать комментарий. Все цены вписывать с НДС.
...

Sheet ОЛ_КОЛОДЦА
B1: ОБЩЕСТВО С ОГРАНИЧЕННОЙ ОТВЕТСТВЕННОСТЬЮ «НОВЫЕ ТРУБНЫЕ ТЕХНОЛОГИИ» 141320, Московская область, г.о. Сергиево-Посадский, д. Коврово, д. 50, помещ. 2 E-mail: info@ntt.su, тел/факс: +7(499) 949-14-04
C4: ОПРОСНЫЙ ЛИСТ КОЛОДЦА
C6: *к заявке ООО «НТТ» № | E6: ОЛ/
C7: Тип колодца | E7: Распределительный
C8: Назначение ОЛ* | D8: → | E8: Материальный расчет
C9: *(выберите одно или несколько назначений) | D9: →
D10: →
D11: →
C12: *Дата заполнения:
C13: *Заказчик:
C14: Стадия проекта:
C15: Объект:
C16: Регион объекта:
C18: Предполагаемые параметры колодца:
C19: *Диаметр рабочей части колодца DN, мм | E19: 2000
C20: *Давление PN, Мпа | E20: 0.1
C21: *Жесткость SN, Па | E21: 5000
C22: Склад | D22: =IF(C22="Производство","Общий метраж выпуска →","Номер заказа →") -> Номер заказа →
C23: Высота возвышения корпуса горловины/корпуса колодца над землей, мм | E23: 300
C24: Установка под проезжей частью (Да/Нет): | E24: Нет
C25: *Глубина рабочей части корпуса (H), мм | E25: 4000
C26: Наличие горловины колодца | E26: Да
C27: Диаметр горловины колодца d,мм | E27: 1200
C28: Высота горловины h (до верха рабочей части емкости), мм | E28: 1800
C30: Лестница | E30: Да
C32: Смола:
C33: Тип смолы | E33: Стандарт
C34: Марка смолы | E34: =VLOOKUP(E33,Списки!$BH$1:$BI$4,2,) -> ИЗО
C35: MAX температура жидкости, оС
C36: Вид стоков | E36: Хозяйственно-бытовые
C37: Возможное MAX внутреннее давление, кг/см2
C39: Параметры патрубков:
C40: подводящего | G40: отводящего
C41: Материал подводящего патрубка | E41: ПЭ | G41: Материал отводящего патрубка | I41: ПЭ
C42: Глубина залегания H лотка, мм | E42: 2000 | G42: Глубина залегания, мм | I42: 2500
C43: Проходной (внутренний) диаметр, DА, мм. | E43: 300 | G43: Проходной (внутренний) диаметр, DB, мм. | I43: 300
C44: Направление подводящего патрубка, в часах | G44: Направление отводящего патрубка, в часах
C45: Количество подводящих патрубков, шт. | E45: 1 | G45: Количество отводящих патрубков, шт. | I45: 2
C47: Наличие дополнительного оборудования: | E47: Да
C48: Наличие дробилки/корзины для мусора | E48: Корзина для мусора
...

Sheet Калькулятор колодца
C1: Материальный расчет | M1: к содержанию
C3: Дата заполнения таблицы | D3: Заказчик/ Объект/ Вид насосной станции/ Параметры | G3: DN трубы, мм | H3: Глубина корп., L мм | I3: Высота возвышения корпуса горловины/корпуса колодца над землей, мм | J3: DN вход. патрубка, мм | K3: Кол-во вход. патрубков, шт | L3: DN вых.патрубка, мм | M3: Кол-во выход. патрубков, шт | N3: Высота горловины, мм
H4: =IF(H5<3000,3000,IF(AND(H5>7000),12000,CEILING(H5,500))) -> 4000 | I4: =CONCATENATE(G5,"-b") -> 2000-b
D5: ="Заявка № "&ОЛ_КОЛОДЦА!E6&" "&ОЛ_КОЛОДЦА!E13&" "&ОЛ_КОЛОДЦА!E15&" "&ОЛ_КОЛОДЦА!E16&" "&G5&"х"&H5&"мм" -> Заявка № ОЛ/ 2000х4000мм | G5: =ОЛ_КОЛОДЦА!E19 -> 2000 | H5: =IF(ОЛ_КОЛОДЦА!E26="да",ОЛ_КОЛОДЦА!E25,ОЛ_КОЛОДЦА!E25+I5) -> 4000 | I5: =ОЛ_КОЛОДЦА!E23 -> 300 | J5: =ОЛ_КОЛОДЦА!E43 -> 300 | K5: =ОЛ_КОЛОДЦА!E45 -> 1 | L5: =ОЛ_КОЛОДЦА!I43 -> 300 | M5: =ОЛ_КОЛОДЦА!I45 -> 2 | N5: =IF(ОЛ_КОЛОДЦА!E26="да",ОЛ_КОЛОДЦА!E28+I5,0) -> 2100
C6: Наименование изделия | D6: Материал изделия | E6: Транспортируемая среда | F6: Давление трубопровода, PN МПа | H6: Жесткость, SN Па | J6: D гильзы для прохода вход.патрубка, мм | L6: D гильзы для прохода выход. труб-да, мм | N6: Диаметр горовины, мм
F7: =IF(AND('Калькулятор колодца'!G8>0.6,OR(CONCATENATE('Калькулятор колодца'!G5,'Калькулятор колодца'!I8)=CONCATENATE('Вес трубы, ПЭ трубы'!B51,'Вес трубы, ПЭ трубы'!C51),CONCATENATE('Калькулятор колодца'!G5,'Калькулятор колодца'!I8)=CONCATENATE('Вес трубы, ПЭ трубы'!B55,'Вес трубы, ПЭ трубы'!C55),CONCATENATE('Калькулятор колодца'!G5,'Калькулятор колодца'!I8)=CONCATENATE('Вес трубы, ПЭ трубы'!B57,'Вес трубы, ПЭ трубы'!C57))),1.6,IF(AND(G5=1300,OR(I8=5000,I8=10000),'Калькулятор колодца'!G8<=0.4),0.4,IF(G8<=0.6,0.6,1))) -> 0.6 | J7: +100 | K7: Вручную | L7: +100 | M7: Вручную
C8: Труба | D8: СК/НПС | E8: К | G8: =ОЛ_КОЛОДЦА!E20 -> 0.1 | I8: =ОЛ_КОЛОДЦА!E21 -> 5000 | K8: =IF(J5>=200,_xlfn.CEILING.MATH(IF(J5<100,J5,J5+100),100),_xlfn.CEILING.MATH(IF(J5<100,J5,J5+100),50)) -> 400 | M8: =IF(L5>=200,_xlfn.CEILING.MATH(IF(L5<100,L5,L5+100),100),_xlfn.CEILING.MATH(IF(L5<100,L5,L5+100),50)) -> 400 | N8: =IF(ОЛ_КОЛОДЦА!E26="нет","0",ОЛ_КОЛОДЦА!E27) -> 1200
B9: № | C9: Категория | D9: Материалы,работы, услуги. | F9: Закупка | G9: Вес, кг/пм | H9: Кол-во за 1 ед. | J9: Общ. кол-во | K9: ЕИ | L9: Цена за 1 ед., руб | N9: Сумма, руб | O9: Примечание | P9: МТО | Q9: Логистика
B11: 1 | D11: =CONCATENATE("Корпус колодца ",G5,"х",H5,"мм"," ","(где ",I5,"мм"," - подземная часть), в т.ч.:") -> Корпус колодца 2000х4000мм (где 300мм - подземная часть), в т.ч.:
B12: 1.1 | D12: Корпус. Материалы
I13: Кол-во корпусов: | J13: 1 | K13: шт
C14: Собственное производство | D14: =IF(C8="","",CONCATENATE(C8," ",D8,"-",E8," ",G5,"-",G8,"-",I8)) -> Труба СК/НПС-К 2000-0,1-5000 | E14: Целая труба | F14: =IF(E14=Списки!AI3,"Справочно","") | G14: =IFERROR(I14*INDEX('Вес трубы, ПЭ трубы'!E:G,MATCH(CONCATENATE(G5&";"&F7&";"&I8),'Вес трубы, ПЭ трубы'!E:E,),3),"") -> 1585.2 | I14: =H5/1000 -> 4 | J14: =IF(H14="",I14,H14) -> 4 | K14: м | L14: 1 | M14: =IFERROR(IF(L14<>"","",VLOOKUP(C14&D14&K14,НН!A:J,10,)),"") | N14: =IFERROR(IF(L14="",M14*J14,J14*L14),"") -> 4
C15: Собственное производство | D15: Придание изделию товарного вида | F15: {=IF(C15="","",IF(OR(C15=Списки!$AG$15:$AG$17),"нет","да"))} -> нет | I15: =$G$5/1300*J14 -> 6.1538462 | J15: =ROUNDUP(IF($E$14=Списки!$AI$2,IF(H15="",I15,H15),0),1) -> 6.2 | K15: чел. ч | M15: =IFERROR(IF(L15<>"","",VLOOKUP(C15&D15&K15,НН!A:J,10,)),"") -> 1207.8 | N15: =IFERROR(IF(L15="",M15*J15,J15*L15),"") -> 7488.36
C16: Собственное производство | D16: =IF(C8="","",CONCATENATE(C8," ",D8,"-",E8," ",G5,"-",G8,"-",I8)) -> Труба СК/НПС-К 2000-0,1-5000 | F16: нет | G16: =IFERROR(I16*INDEX('Вес трубы, ПЭ трубы'!E:G,MATCH(CONCATENATE(#REF!&";"&F8&";"&#REF!),'Вес трубы, ПЭ трубы'!E:E,),3),"") | J16: =IF($E$14=Списки!$AI$2,0,IF(H16="",I16,H16)) -> 0 | K16: м | M16: =IFERROR(IF(L16<>"","",VLOOKUP(C16&D16&K16,НН!A:J,10,)),"") | N16: =IFERROR(IF(L16="",SUM(#REF!),J16*L16),0) -> 0
C17: Собственное производство | D17: Придание изделию товарного вида | F17: {=IF(C17="","",IF(OR(C17=Списки!$AG$15:$AG$17),"нет","да"))} -> нет | I17: =$G$5/1300*J16 -> 0 | J17: =ROUNDUP(IF(H17="",I17,H17),1) -> 0 | K17: чел. ч | M17: =IFERROR(IF(L17<>"","",VLOOKUP(C17&D17&K17,НН!A:J,10,)),"") -> 1207.8 | N17: =IFERROR(IF(L17="",M17*J17,J17*L17),"") -> 0
C18: Собственное производство | D18: =IF(C8="","",CONCATENATE(C8," ",D8,"-",E8," ",G5,"-",G8,"-",I8)) -> Труба СК/НПС-К 2000-0,1-5000 | F18: нет | J18: =IF($E$14=Списки!$AI$2,0,IF(H18="",I18,H18)) -> 0 | K18: м | M18: =IFERROR(IF(L18<>"","",VLOOKUP(C18&D18&K18,НН!A:J,10,)),"") | N18: =IFERROR(IF(L18="",SUM(#REF!),J18*L18),0) -> 0
C19: Собственное производство | D19: Придание изделию товарного вида | F19: {=IF(C19="","",IF(OR(C19=Списки!$AG$15:$AG$17),"нет","да"))} -> нет | I19: =$G$5/1300*J18 -> 0 | J19: =ROUNDUP(IF(H19="",I19,H19),1) -> 0 | K19: чел. ч | M19: =IFERROR(IF(L19<>"","",VLOOKUP(C19&D19&K19,НН!A:J,10,)),"") -> 1207.8 | N19: =IFERROR(IF(L19="",M19*J19,J19*L19),"") -> 0
C20: Собственное производство | D20: =IF(C8="","",CONCATENATE("Муфта-1 ",D8,"-",E8," ",G5,"-",1)) -> Муфта-1 СК/НПС-К 2000-1 | F20: нет | H20: 1 | J20: =IF($E$14=Списки!$AI$2,0,IF(H20="",I20,H20)) -> 0 | K20: шт | M20: =IFERROR(IF(L20<>"","",VLOOKUP(C20&D20&K20,НН!A:J,10,)),"") | N20: =IFERROR(IF(L20="",M20*J20,J20*L20),0) -> 0
C21: Собственное производство | D21: =IF(C43="да","Механическое формованное дно","Механическая формовка плоского днища") -> Механическое формованное дно | F21: {=IF(C21="","",IF(OR(C21=Списки!$AG$15:$AG$17),"нет","да"))} -> нет | I21: =((PI()*(($G$5+300)/(1000*2))^2)*0.01*1850)+(((G5/1000)^2*PI()*0.008*1850)/4) -> 123.35856 | J21: =IF(H21="",I21,H21) -> 123.35856 | K21: кг | M21: =IFERROR(IF(L21<>"","",VLOOKUP(C21&D21&K21,НН!A:J,10,)),"") -> 214.4 | N21: =IFERROR(IF(L21="",M21*J21,J21*L21),"") -> 26448.076
C22: ФОТ | D22: ФОТ | F22: {=IF(C22="","",IF(OR(C22=Списки!$AG$15:$AG$17),"нет","да"))} -> нет | I22: =IF(COUNTIF(D21,"*мех*")=1,0.28,IF(COUNTIF(D21,"*ламин*")=1,0.56,1)) -> 0.28 | J22: =ROUNDUP(IF(H22="",IFERROR(J21*I22,""),H22),1) -> 34.6 | K22: чел. ч | M22: =IFERROR(IF(L22<>"","",VLOOKUP(C22&D22&K22,НН!A:J,10,)),"") -> 1207.8 | N22: =IFERROR(IF(L22="",M22*J22,J22*L22),"") -> 41789.88
C23: Собственное производство | D23: =IF(C43="да","Ламинирование дна к фальшполу","Ламинирование плоского днища") -> Ламинирование дна к фальшполу | F23: {=IF(C23="","",IF(OR(C23=Списки!$AG$15:$AG$17),"нет","да"))} -> нет | I23: =IF(H23="",IFERROR(IF(H21="",J21,H21)*3/10,""),"") -> 37.007569 | J23: =IF(H23="",I23,H23) -> 37.007569 | K23: кг | M23: =IFERROR(IF(L23<>"","",VLOOKUP(C23&D23&K23,НН!A:J,10,)),"") -> 310.2 | N23: =IFERROR(IF(L23="",M23*J23,J23*L23),"") -> 11479.748
C24: ФОТ | D24: ФОТ | F24: {=IF(C24="","",IF(OR(C24=Списки!$AG$15:$AG$17),"нет","да"))} -> нет | I24: =IF(COUNTIF(D23,"*мех*")=1,0.28,IF(COUNTIF(D23,"*ламин*")=1,0.56,1)) -> 0.56 | J24: =ROUNDUP(IF(H24="",IFERROR(J23*I24,""),H24),1) -> 20.8 | K24: чел. ч | M24: =IFERROR(IF(L24<>"","",VLOOKUP(C24&D24&K24,НН!A:J,10,)),"") -> 1207.8 | N24: =IFERROR(IF(L24="",M24*J24,J24*L24),"") -> 25122.24
D25: Входящий патрубок
C26: Собственное производство | D26: =IF('Калькулятор колодца'!E41="Труба стеклокомпозитная","Муфта-2 СК/НПС-К "&J$5&"-1",IF(ОЛ_КОЛОДЦА!E41=Списки!L$8,IF(J$5>=300,"Труба СК/НПС-К "&K$8&"-0,1-2500","Ручная формовка патрубка"),IF(J$5>=200,"Труба СК/НПС-К "&_xlfn.CEILING.MATH(IF(J$8="",K$8,J$8),50)&"-0,1-2500","Ручная формовка патрубка"))) -> Труба СК/НПС-К 400-0,1-2500 | E26: =IF('Калькулятор колодца'!E41="Труба стеклокомпозитная","Муфта-2 СК/НПС-К "&J$5&"-1","Стеклокомпозитная гильза Ø"&K$8) -> Стеклокомпозитная гильза Ø400 | F26: {=IF(C26="","",IF(OR(C26=Списки!$AG$15:$AG$17),"нет","да"))} -> нет | J26: =IFERROR(IF(SEARCH("*гильза*",E26)=1,0.5*$K$5),VLOOKUP(IF(J8="",K8,J8),'Для расчетов'!$A$36:$F$60,4,)*$K$5) -> 0.5 | K26: =IFERROR(IF(SEARCH("*труба*",D26)=1,"м"),"кг") -> м | L26: =IFERROR(IF(SEARCH("м",K26)=1,"1.00"),"") -> 1.00 | M26: =IFERROR(IF(L26<>"","",VLOOKUP(C26&D26&K26,НН!A:J,10,)),"") | N26: =IFERROR(IF(L26="",M26*J26,J26*L26),0) -> 0
C27: Собственное производство | D27: Придание изделию товарного вида | I27: =K8/1300*J26 -> 0.15384615 | J27: =IF(COUNTIF(D26,"*труба*")=1,K8/1300*J26,0) -> 0.15384615 | K27: чел. ч | M27: =IFERROR(IF(L27<>"","",VLOOKUP(C27&D27&K27,НН!A:J,10,)),"") -> 1207.8 | N27: =IFERROR(IF(L27="",M27*J27,J27*L27),"") -> 185.81538
C28: Собственное производство | D28: =IFERROR(IF(SEARCH("*муфта*",E26)=1,"Ламинирование проходной муфты к корпусу"),"Ламинирование патрубка к корпусу") -> Ламинирование патрубка к корпусу | F28: {=IF(C28="","",IF(OR(C28=Списки!$AG$15:$AG$17),"нет","да"))} -> нет | J28: =IF(OR(ОЛ_КОЛОДЦА!$E$43="",ОЛ_КОЛОДЦА!$E$45=""),0,IFERROR(IF(SEARCH("*муфта*",E26)=1,VLOOKUP(IF(J8="",K8,J8),'Для расчетов'!$A$36:$F$60,4,)*3/10*$K$5),VLOOKUP(IF(J8="",K8,J8),'Для расчетов'!$A$36:$F$60,4,)*$K$5*3/10)) -> 0.33 | K28: кг | M28: =IFERROR(IF(L28<>"","",VLOOKUP(C28&D28&K28,НН!A:J,10,)),"") -> 310.2 | N28: =IFERROR(IF(L28="",M28*J28,J28*L28),"") -> 102.366
C29: ФОТ | D29: ФОТ | F29: {=IF(C29="","",IF(OR(C29=Списки!$AG$15:$AG$17),"нет","да"))} -> нет | I29: =IF(COUNTIF(D28,"*мех*")=1,0.28,IF(COUNTIF(D28,"*ламин*")=1,1)) -> 1 | J29: =ROUNDUP(IF(OR(ОЛ_КОЛОДЦА!$E$43="",ОЛ_КОЛОДЦА!$E$45=""),0,IF(H29="",IFERROR(J28*I29,""),H29)),1) -> 0.4 | K29: чел. ч | M29: =IFERROR(IF(L29<>"","",VLOOKUP(C29&D29&K29,НН!A:J,10,)),"") -> 1207.8 | N29: =IFERROR(IF(L29="",M29*J29,J29*L29),"") -> 483.12 | O29: ламинирование патрубка/муфты к корпуск коэффициент = 1
D30: Выходящий патрубок
C31: Собственное производство | D31: =IF(ОЛ_КОЛОДЦА!I41=Списки!L$8,IF(L$5>=300,"Труба СК/НПС-К "&M$8&"-0,1-2500","Ручная формовка патрубка"),IF(L$5>=200,"Труба СК/НПС-К "&_xlfn.CEILING.MATH(IF(L$8="",M$8,L$8),50)&"-0,1-2500","Ручная формовка патрубка")) -> Труба СК/НПС-К 400-0,1-2500 | E31: =IF(ОЛ_КОЛОДЦА!I41="Труба стеклокомпозитная","Муфта-2 СК/НПС-К "&L$5&"-1","Стеклокомпозитная гильза Ø"&M$8) -> Стеклокомпозитная гильза Ø400 | F31: {=IF(C31="","",IF(OR(C31=Списки!$AG$15:$AG$17),"нет","да"))} -> нет | J31: =IFERROR(IF(SEARCH("*гильза*",E31)=1,0.5*$M$5),VLOOKUP(IF(L8="",M8,L8),'Для расчетов'!$A$36:$F$60,4,)*$M$5) -> 1 | K31: =IFERROR(IF(SEARCH("*труба*",D31)=1,"м"),"кг") -> м | L31: =IFERROR(IF(SEARCH("м",K31)=1,"1.00"),"") -> 1.00 | M31: =IFERROR(IF(L31<>"","",VLOOKUP(C31&D31&K31,НН!A:J,10,)),"") | N31: =IFERROR(IF(L31="",M31*J31,J31*L31),0) -> 0
C32: Собственное производство | D32: Придание изделию товарного вида | F32: {=IF(C32="","",IF(OR(C32=Списки!$AG$15:$AG$17),"нет","да"))} -> нет | I32: =M8/1300*J31 -> 0.30769231 | J32: =IF(COUNTIF(D31,"*труба*")=1,M8/1300*J31,0) -> 0.30769231 | K32: чел. ч | M32: =IFERROR(IF(L32<>"","",VLOOKUP(C32&D32&K32,НН!A:J,10,)),"") -> 1207.8 | N32: =IFERROR(IF(L32="",M32*J32,J32*L32),"") -> 371.63077
C33: Собственное производство | D33: =IFERROR(IF(SEARCH("*муфта*",E31)=1,"Ламинирование проходной муфты к корпусу"),"Ламинирование патрубка к корпусу") -> Ламинирование патрубка к корпусу | F33: {=IF(C33="","",IF(OR(C33=Списки!$AG$15:$AG$17),"нет","да"))} -> нет | J33: =IF(OR(ОЛ_КОЛОДЦА!$I$43="",ОЛ_КОЛОДЦА!$I$45=""),0,IFERROR(IF(SEARCH("*муфта*",E31)=1,VLOOKUP(IF(J8="",K8,J8),'Для расчетов'!$A$36:$F$60,4,)*3/10*$M$5),VLOOKUP(IF(J8="",K8,J8),'Для расчетов'!$A$36:$F$60,4,)*$M$5*3/10)) -> 0.66 | K33: кг | M33: =IFERROR(IF(L33<>"","",VLOOKUP(C33&D33&K33,НН!A:J,10,)),"") -> 310.2 | N33: =IFERROR(IF(L33="",M33*J33,J33*L33),"") -> 204.732
C34: ФОТ | D34: ФОТ | F34: {=IF(C34="","",IF(OR(C34=Списки!$AG$15:$AG$17),"нет","да"))} -> нет | I34: =IF(COUNTIF(D33,"*мех*")=1,0.28,IF(COUNTIF(D33,"*ламин*")=1,1)) -> 1 | J34: =ROUNDUP(IF(OR(ОЛ_КОЛОДЦА!$I$43="",ОЛ_КОЛОДЦА!$I$45=""),0,IF(H34="",IFERROR(J33*I34,""),H34)),1) -> 0.7 | K34: чел. ч | M34: =IFERROR(IF(L34<>"","",VLOOKUP(C34&D34&K34,НН!A:J,10,)),"") -> 1207.8 | N34: =IFERROR(IF(L34="",M34*J34,J34*L34),"") -> 845.46 | O34: ламинирование патрубка/муфты к корпуск коэффициент = 1
C36: =ОЛ_КОЛОДЦА!E26 -> Да | D36: Горловина для колодца: | E36: DN: | F36: =N8 -> 1200 | G36: SN: | H36: 2500 | I36: PN: | J36: 0.1 | K36: кол-во: | L36: 1 | M36: шт.
C37: Собственное производство | D37: ="Труба СК/НПС-К "&F36&"-"&J36&"-"&H36 -> Труба СК/НПС-К 1200-0,1-2500 | E37: Заготовка трубы для горловины колодца | F37: {=IF(C37="","",IF(OR(C37=Списки!$AG$15:$AG$17),"нет","да"))} -> нет | I37: =N5/1000 -> 2.1 | J37: =IF(ОЛ_КОЛОДЦА!E26="нет",0,IF(H37="",I37,H37)*L36) -> 2.1 | K37: м | L37: 1 | M37: =IFERROR(IF(L37<>"","",VLOOKUP(C37&D37&K37,НН!A:J,10,)),"") | N37: =IFERROR(IF(L37="",SUM(#REF!),J37*L37),0) -> 2.1
C38: Собственное производство | D38: Придание изделию товарного вида | F38: {=IF(C38="","",IF(OR(C38=Списки!$AG$15:$AG$17),"нет","да"))} -> нет | I38: =$F$36/1300*J37 -> 1.9384615 | J38: =ROUNDUP(IF(H38="",I38,H38),1) -> 2 | K38: чел. ч | M38: =IFERROR(IF(L38<>"","",VLOOKUP(C38&D38&K38,НН!A:J,10,)),"") -> 1207.8 | N38: =IFERROR(IF(L38="",M38*J38,J38*L38),"") -> 2415.6
C39: Собственное производство | D39: ="Муфта соединительная Муфта-1 "&F36&"-1" -> Муфта соединительная Муфта-1 1200-1 | E39: Да | F39: {=IF(C39="","",IF(OR(C39=Списки!$AG$15:$AG$17),"нет","да"))} -> нет | I39: 1 | J39: =IF(E39="нет",0,IF(C36="нет",0,IF(H39="",I39,H39)))*L36 -> 1 | K39: шт | L39: 1 | M39: =IFERROR(IF(L39<>"","",VLOOKUP(C39&D39&K39,НН!A:J,10,)),"") | N39: =IFERROR(IF(L39="",M39*J39,J39*L39),"") -> 1
C40: Собственное производство | D40: Ламинирование горловины к корпусу емкости | F40: {=IF(C40="","",IF(OR(C40=Списки!$AG$15:$AG$17),"нет","да"))} -> нет | I40: =IF(ОЛ_КОЛОДЦА!E26="нет",0,VLOOKUP(F36,'Для расчетов'!$A$36:$F$72,4,)) -> 10.3 | J40: =IF($C$36="нет",0,IF(H40="",I40,H40))*L36 -> 10.3 | K40: кг | M40: =IFERROR(IF(L40<>"","",VLOOKUP(C40&D40&K40,НН!A:J,10,)),"") -> 310.2 | N40: =IFERROR(IF(L40="",M40*J40,J40*L40),"") -> 3195.06
C41: ФОТ | D41: ФОТ | F41: {=IF(C41="","",IF(OR(C41=Списки!$AG$15:$AG$17),"нет","да"))} -> нет | I41: =IF(COUNTIF(D40,"*мех*")=1,0.28,IF(COUNTIF(D40,"*ламин*")=1,0.56,1)) -> 0.56 | J41: =ROUNDUP(IF($C$36="нет",0,IFERROR(IF(H41="",J40*I41,H41),"")),1) -> 5.8 | K41: чел. ч | M41: =IFERROR(IF(L41<>"","",VLOOKUP(C41&D41&K41,НН!A:J,10,)),"") -> 1207.8 | N41: =IFERROR(IF(L41="",M41*J41,J41*L41),"") -> 7005.24
F42: {=IF(ISBLANK(C42),"",IF(OR(C42=Списки!$AG$15:$AG$17),"нет","да"))} | J42: =IF(ISBLANK(D42),"",IF(H42="",I42,H42)) | M42: =IFERROR(IF(L42<>"","",VLOOKUP(C42&D42&K42,НН!A:J,10,)),"") | N42: =IFERROR(IF(L42="",M42*J42,J42*L42),"")
C43: Да | D43: Фальшпол:
...

Sheet ОЛ_ЕМКОСТИ
B1: ОБЩЕСТВО С ОГРАНИЧЕННОЙ ОТВЕТСТВЕННОСТЬЮ «НОВЫЕ ТРУБНЫЕ ТЕХНОЛОГИИ» 141320, Московская область, г.о. Сергиево-Посадский, д. Коврово, д. 50, помещ. 2 E-mail: info@ntt.su, тел/факс: +7(499) 949-14-04
C4: ОПРОСНЫЙ ЛИСТ ЕМКОСТИ
C6: *к заявке ООО «НТТ» № | E6: ОЛ/
C7: Тип емкости
C8: Назначение ОЛ* | D8: → | E8: Материальный расчет
C9: *(выберите одно или несколько назначений) | D9: →
D10: →
D11: →
C12: *Дата заполнения:
C13: *Заказчик:
C14: Стадия проекта: | E14: проект
C15: Объект:
C16: Регион объекта:
C18: Предполагаемый размер емкости*: | E18: Ручной ввод | F18: Расчет
C19: *Объем, м3 | E19: 100 | F19: =IF(E19="",VLOOKUP(ОЛ_ЕМКОСТИ!$E$24&ОЛ_ЕМКОСТИ!$E$25&ОЛ_ЕМКОСТИ!$E$39,'для шапки'!$B$2:$I$9,8,),"")
C20: *Диаметр DN, мм | E20: 3000
C21: *Давление PN, Мпа | D21: ВАЖНО от выбранного давления зависит масса формованных слоев на стыке (кг) | E21: 0.1
C22: *Жесткость SN, Па | E22: 10000
C23: Производство | D23: =IF(C23="Производство","Общий метраж выпуска →","Номер заказа →") -> Общий метраж выпуска →
C24: Расположение | E24: Горизонтальное | I24: =E24&E25 -> ГоризонтальноеПодземная
C25: Установка | E25: Подземная
C26: Высота возвышения корпуса емкости/шахты обслуживания над землей, мм | E26: 300
C27: Установка под проезжей частью (Да/Нет): | E27: Нет
C28: Длина рабочей части емкости при горизонтальном расположении, мм | F28: =IF(E28="",VLOOKUP(ОЛ_ЕМКОСТИ!$E$24&ОЛ_ЕМКОСТИ!$E$25&ОЛ_ЕМКОСТИ!$E$39,'для шапки'!$B$2:$I$9,2,),"") -> 13400
C29: Длина рабочей части емкости при вертикальном расположении, мм | E29: 4000 | F29: =IF(E29="",VLOOKUP(ОЛ_ЕМКОСТИ!$E$24&ОЛ_ЕМКОСТИ!$E$25&ОЛ_ЕМКОСТИ!$E$39,'для шапки'!$B$2:$L$9,11,),"")
C31: Смола:
C33: Тип смолы | E33: Стандарт
C34: Марка смолы | E34: =VLOOKUP(E33,Списки!$BH$1:$BI$4,2,) -> ИЗО
C35: MAX температура жидкости, оС
C36: Вид стоков | E36: Производственные
C37: Возможное MAX внутреннее давление, кг/см2
C39: Наличие шахты обслуживания | E39: Да
C40: Диаметр шахты d,мм | E40: 1200
C41: Высота шахты h (до верха рабочей части емкости), мм | E41: 2000
C43: Лестница | E43: Да
C45: Параметры патрубков:
C47: подводящего: | G47: отводящего:
C48: Материал патрубка | E48: ПЭ | G48: Материал патрубка | I48: ПЭ
C49: *Номинальный диаметр патрубка DN, мм | E49: 400 | G49: *Номинальный диаметр патрубка DN, мм | I49: 300
C50: Кол-во патрубков | E50: 1 | G50: Кол-во патрубков | I50: 2
...

Sheet Калькулятор ЕМК
C1: Материальный расчет | M1: к содержанию
C3: Дата заполнения таблицы | D3: Заказчик/ Объект/ Вид емкости/ Параметры | G3: DN трубы, мм | H3: Габаритная длина рабочей части емкости, L мм | I3: =IF(ОЛ_ЕМКОСТИ!E24="горизонтальное",IF(ОЛ_ЕМКОСТИ!E39="да","Длина трубы для емкости при горизонтальном расположении с шахтой обслуживания, мм","Длина трубы для емкости при горизонтальном расположении без шахты обслуживания, мм"),IF(ОЛ_ЕМКОСТИ!E39="да","Длина трубы для емкости при вертикальном расположении с шахтой обслуживания, мм","Длина трубы для емкости при вертикальном расположении без шахты обслуживания, мм")) -> Длина трубы для емкости при горизонтальном расположении с шахтой обслуживания, мм | J3: Высота возвышения корпуса емкости/шахты обслуживания над землей, мм | K3: Объем емкости, м3 | L3: Объем 2х элиптических днищ для горизонтальной установки, м3 | M3: Количество одинаковых линий
H4: =IF(H5<3000,3000,IF(AND(H5>7000),12000,CEILING(H5,500))) -> 12000 | I4: =IF(I5<3000,3000,IF(AND(I5>7000),12000,CEILING(I5,500))) -> 12000
D5: ="Заявка № "&ОЛ_ЕМКОСТИ!E6&" Заказчик: "&ОЛ_ЕМКОСТИ!E13&" "&ОЛ_ЕМКОСТИ!E15&" "&ОЛ_ЕМКОСТИ!E7&" емкость "&G5&"х"&H5&"мм" -> Заявка № ОЛ/ Заказчик: емкость 3000х13400мм | G5: =ОЛ_ЕМКОСТИ!E20 -> 3000 | H5: =INDEX('для шапки'!$C$2:$K$11,MATCH(ОЛ_ЕМКОСТИ!$E$24&ОЛ_ЕМКОСТИ!$E$25&ОЛ_ЕМКОСТИ!$E$39,'для шапки'!$B$2:$B$11,),MATCH('Калькулятор ЕМК'!H3,'для шапки'!$C$1:$K$1,)) -> 13400 | I5: =INDEX('для шапки'!$C$2:$K$11,MATCH(ОЛ_ЕМКОСТИ!$E$24&ОЛ_ЕМКОСТИ!$E$25&ОЛ_ЕМКОСТИ!$E$39,'для шапки'!$B$2:$B$11,),MATCH('Калькулятор ЕМК'!I3,'для шапки'!$C$1:$K$1,)) -> 13400 | J5: =INDEX('для шапки'!$C$2:$K$11,MATCH(ОЛ_ЕМКОСТИ!$E$24&ОЛ_ЕМКОСТИ!$E$25&ОЛ_ЕМКОСТИ!$E$39,'для шапки'!$B$2:$B$11,),MATCH('Калькулятор ЕМК'!J3,'для шапки'!$C$1:$K$1,)) -> 300 | K5: =INDEX('для шапки'!$C$2:$K$11,MATCH(ОЛ_ЕМКОСТИ!$E$24&ОЛ_ЕМКОСТИ!$E$25&ОЛ_ЕМКОСТИ!$E$39,'для шапки'!$B$2:$B$11,),MATCH('Калькулятор ЕМК'!K3,'для шапки'!$C$1:$K$1,)) -> 100 | L5: =(PI()*((G5/1000)^3))/15 -> 5.6548668 | M5: 1
C6: Наименование изделия | D6: Материал изделия | E6: Транспортируемая среда | F6: Давление трубопровода, PN МПа | H6: Жесткость, SN Па | K6: D шахты обслуживания, мм | L6: Количество шахт, шт. | M6: Высота шахты h (до верха рабочей части емкости), мм | N6: Кол-во емкостей
F7: =IF(AND('Калькулятор ЕМК'!G8>0.6,OR(CONCATENATE('Калькулятор ЕМК'!G5,'Калькулятор ЕМК'!H8)=CONCATENATE('Вес трубы, ПЭ трубы'!B51,'Вес трубы, ПЭ трубы'!C51),CONCATENATE('Калькулятор ЕМК'!G5,'Калькулятор ЕМК'!H8)=CONCATENATE('Вес трубы, ПЭ трубы'!B55,'Вес трубы, ПЭ трубы'!C55),CONCATENATE('Калькулятор ЕМК'!G5,'Калькулятор ЕМК'!H8)=CONCATENATE('Вес трубы, ПЭ трубы'!B57,'Вес трубы, ПЭ трубы'!C57))),1.6,IF(AND(G5=1300,OR(H8=5000,H8=10000),'Калькулятор ЕМК'!G8<=0.4),0.4,IF(G8<=0.6,0.6,1))) -> 0.6 | G7: =IF(G8<=0.6,0.6,1) -> 0.6 | J7: +100 | K7: Вручную | L7: +100 | M7: =IF(M8*1000<3000,3000,IF(AND(M8*1000>7000,M8*1000<12000),12000,CEILING(M8*1000,500))) -> 2000000
C8: Труба | D8: =IF(ОЛ_ЕМКОСТИ!$E$7=Списки!$AO$3,"СК/ВЭС","СК/НПС") -> СК/НПС | E8: К | G8: =ОЛ_ЕМКОСТИ!E21 -> 0.1 | H8: =ОЛ_ЕМКОСТИ!E22 -> 10000 | K8: =IF(ОЛ_ЕМКОСТИ!E39="нет","0",ОЛ_ЕМКОСТИ!E40) -> 1200 | L8: 2 | M8: =IF(ОЛ_ЕМКОСТИ!E39="нет","0",ОЛ_ЕМКОСТИ!E41) -> 2000 | N8: 1
B9: № | C9: Категория | D9: Материалы,работы, услуги. | F9: Закупка | G9: Вес, кг/пм | H9: Кол-во за 1 ед. | J9: Общ. кол-во | K9: ЕИ | L9: Цена за 1 ед., руб | N9: Сумма, руб | O9: Примечание | P9: МТО | Q9: Логистика
B11: 1 | D11: =CONCATENATE("Корпус емкости"," ",G5,"х",H5,"мм"," ",", в т.ч.:") -> Корпус емкости 3000х13400мм , в т.ч.:
B12: 1.1 | D12: Корпус емкости. Материалы
C13: Собственное производство | D13: =IF(C8="","",CONCATENATE(C8," ",D8,"-",E8," ",G5,"-",G8,"-",H8)) -> Труба СК/НПС-К 3000-0,1-10000 | E13: Целая труба | F13: =IF(E13=Списки!AI3,"Справочно","") | G13: =IFERROR(I13*INDEX('Вес трубы, ПЭ трубы'!E:G,MATCH(CONCATENATE(G5&";"&F7&";"&H8),'Вес трубы, ПЭ трубы'!E:E,),3),"") -> 14455.98 | I13: =IF(C24="Старый способ",I5/1000*M5,((I5/1000+1.5)*M5)) -> 14.9 | J13: =IF(H13="",I13,H13) -> 14.9 | K13: м | L13: 1 | M13: =IFERROR(IF(L13<>"","",VLOOKUP(C13&D13&K13,НН!A:J,10,)),"") | N13: =IFERROR(IF(L13="",M13*J13,J13*L13),"") -> 14.9
C14: Собственное производство | D14: Придание изделию товарного вида | F14: {=IF(C14="","",IF(OR(C14=Списки!$AG$15:$AG$17),"нет","да"))} -> нет | I14: =$G$5/1300*J13 -> 34.384615 | J14: =ROUNDUP(IF($E$13=Списки!$AI$2,IF(H14="",I14,H14),0),1) -> 34.4 | K14: чел. ч | M14: =IFERROR(IF(L14<>"","",VLOOKUP(C14&D14&K14,НН!A:J,10,)),"") -> 1207.8 | N14: =IFERROR(IF(L14="",M14*J14,J14*L14),"") -> 41548.32
C15: Собственное производство | D15: =IF(C8="","",CONCATENATE(C8," ",D8,"-",E8," ",G5,"-",G8,"-",H8)) -> Труба СК/НПС-К 3000-0,1-10000 | F15: нет | G15: =IFERROR(I15*INDEX('Вес трубы, ПЭ трубы'!E:G,MATCH(CONCATENATE(#REF!&";"&F7&";"&#REF!),'Вес трубы, ПЭ трубы'!E:E,),3),"") | H15: 4.34 | J15: =IF(ОЛ_ЕМКОСТИ!$E$24=Списки!$AK$2,0,IF($E$13=Списки!$AI$2,0,IF(H15="",I15,H15))) -> 0 | K15: м | M15: =IFERROR(IF(L15<>"","",VLOOKUP(C15&D15&K15,НН!A:J,10,)),"") | N15: =IFERROR(IF(L15="",SUM(#REF!),J15*L15),0) -> 0
C16: Собственное производство | D16: Придание изделию товарного вида | F16: {=IF(C16="","",IF(OR(C16=Списки!$AG$15:$AG$17),"нет","да"))} -> нет | I16: =$G$5/1300*J15 -> 0 | J16: =ROUNDUP(IF(H16="",I16,H16),1) -> 0 | K16: чел. ч | M16: =IFERROR(IF(L16<>"","",VLOOKUP(C16&D16&K16,НН!A:J,10,)),"") -> 1207.8 | N16: =IFERROR(IF(L16="",M16*J16,J16*L16),"") -> 0
C17: Собственное производство | D17: =IF(C8="","",CONCATENATE(C8," ",D8,"-",E8," ",G5,"-",G8,"-",H8)) -> Труба СК/НПС-К 3000-0,1-10000 | F17: нет | H17: 4 | J17: =IF(ОЛ_ЕМКОСТИ!$E$24=Списки!$AK$2,0,IF($E$13=Списки!$AI$2,0,IF(H17="",I17,H17))) -> 0 | K17: м | M17: =IFERROR(IF(L17<>"","",VLOOKUP(C17&D17&K17,НН!A:J,10,)),"") | N17: =IFERROR(IF(L17="",SUM(#REF!),J17*L17),0) -> 0
C18: Собственное производство | D18: Придание изделию товарного вида | F18: {=IF(C18="","",IF(OR(C18=Списки!$AG$15:$AG$17),"нет","да"))} -> нет | I18: =$G$5/1300*J17 -> 0 | J18: =ROUNDUP(IF(H18="",I18,H18),1) -> 0 | K18: чел. ч | M18: =IFERROR(IF(L18<>"","",VLOOKUP(C18&D18&K18,НН!A:J,10,)),"") -> 1207.8 | N18: =IFERROR(IF(L18="",M18*J18,J18*L18),"") -> 0
C19: Собственное производство | D19: =IF(C8="","",CONCATENATE("Муфта-1 ",D8,"-",E8," ",G5,"-",1)) -> Муфта-1 СК/НПС-К 3000-1 | F19: нет | H19: 1 | J19: =IF(ОЛ_ЕМКОСТИ!$E$24=Списки!$AK$2,0,IF($E$13=Списки!$AI$2,0,IF(H19="",I19,H19))) -> 0 | K19: шт | M19: =IFERROR(IF(L19<>"","",VLOOKUP(C19&D19&K19,НН!A:J,10,)),"") | N19: =IFERROR(IF(L19="",M19*J19,J19*L19),0) -> 0
C20: Собственное производство | D20: Ламинирование стыков частей трубы | F20: нет | J20: =IF(ОЛ_ЕМКОСТИ!$E$24=Списки!$AK$2,0,IF($E$13=Списки!$AI$2,0,IF(H20="",I20,H20))) -> 0 | K20: кг | M20: =IFERROR(IF(L20<>"","",VLOOKUP(C20&D20&K20,НН!A:J,10,)),"") | N20: =IFERROR(IF(L20="",M20*J20,J20*L20),0) -> 0
C21: ФОТ | D21: ФОТ | F21: нет | H21: 0.56 | J21: =IF(ОЛ_ЕМКОСТИ!$E$24=Списки!$AK$2,0,IF($E$13=Списки!$AI$2,0,IF(H21="",I21,H21))) -> 0 | K21: чел. ч | M21: =IFERROR(IF(L21<>"","",VLOOKUP(C21&D21&K21,НН!A:J,10,)),"") -> 1207.8 | N21: =IFERROR(IF(L21="",M21*J21,J21*L21),0) -> 0
G22: Транспортировочная длина трубы (отрезок): | H22: 6 | K22: м
C23: Собственное производство | D23: ="Муфта соединительная Муфта-1 "&G5&"-1" -> Муфта соединительная Муфта-1 3000-1 | F23: {=IF(C23="","",IF(OR(C23=Списки!$AG$15:$AG$17),"нет","да"))} -> нет | I23: =ROUNDDOWN((I5/1000-1.5)/H22,0) -> 1 | J23: =IF(ОЛ_ЕМКОСТИ!$E$24=Списки!AK3,0,IF(H23="",I23,H23)*M5) -> 1 | K23: шт | L23: 1 | M23: =IFERROR(IF(L23<>"","",VLOOKUP(C23&D23&K23,НН!A:J,10,)),"") | N23: =IFERROR(IF(L23="",M23*J23,J23*L23),"") -> 1
C24: Новый способ | E24: ВАЖНО от выбранного давления зависит масса формованных слоев на стыке (кг)
C25: Собственное производство | D25: =IF(C24="новый способ","Ламинация днища (косые и центральный стыки)",IF(ОЛ_ЕМКОСТИ!$E$24="горизонтальное","Механическая формовка эллиптических днищ",IF($C$72="да","Механическое формованное дно", "Механическая формовка плоского днища"))) -> Ламинация днища (косые и центральный стыки) | F25: {=IF(C25="","",IF(OR(C25=Списки!$AG$15:$AG$17),"нет","да"))} -> нет | I25: =((VLOOKUP(G5,'Для расчетов'!J36:S143,9,0))/0.707+(VLOOKUP(G5,'Для расчетов'!J36:S143,9,0))/2)*2 -> 428.83168 | J25: =IF(H25="",I25,H25)*M5 -> 428.83168 | K25: кг | M25: =IFERROR(IF(L25<>"","",VLOOKUP(C25&D25&K25,НН!A:J,10,)),"") -> 214.4 | N25: =IFERROR(IF(L25="",M25*J25,J25*L25),"") -> 91941.513
C26: ФОТ | D26: ФОТ | F26: {=IF(C26="","",IF(OR(C26=Списки!$AG$15:$AG$17),"нет","да"))} -> нет | I26: =IF(C24="старый способо",IF(COUNTIF(D25,"*мех*")=1,0.28,IF(COUNTIF(D25,"*ламин*")=1,0.56,1)),IF(COUNTIF(D25,"*мех*")=1,0.28,IF(COUNTIF(D25,"*ламин*")=1,0.56,1))) -> 0.56 | J26: =ROUNDUP(IF(H26="",IFERROR(J25*I26,""),H26),1) -> 240.2 | K26: чел. ч | M26: =IFERROR(IF(L26<>"","",VLOOKUP(C26&D26&K26,НН!A:J,10,)),"") -> 1207.8 | N26: =IFERROR(IF(L26="",M26*J26,J26*L26),"") -> 290113.56
C27: Собственное производство | D27: =IF(ОЛ_ЕМКОСТИ!E24=Списки!AK2,"Ламинирование эллиптического днища к корпусу",IF($C$72="да","Ламинирование дна к фальшполу","Ламинирование плоского днища к корпусу")) -> Ламинирование эллиптического днища к корпусу | F27: {=IF(C27="","",IF(OR(C27=Списки!$AG$15:$AG$17),"нет","да"))} -> нет | I27: =IF(H27="",IFERROR(IF(H25="",J25,H25)*3/10,""),"") -> 128.6495 | J27: =IFERROR(IF(C24="новый способ",0,),"0") -> 0 | K27: кг | M27: =IFERROR(IF(L27<>"","",VLOOKUP(C27&D27&K27,НН!A:J,10,)),"") -> 310.2 | N27: =IFERROR(IF(L27="",M27*J27,J27*L27),"") -> 0 | O27: расчет при новом способе: =(Мф/0,707 + Мф/2)*М5
C28: ФОТ | D28: ФОТ | F28: {=IF(C28="","",IF(OR(C28=Списки!$AG$15:$AG$17),"нет","да"))} -> нет | I28: =IF(COUNTIF(D27,"*мех*")=1,0.28,IF(COUNTIF(D27,"*ламин*")=1,0.56,1)) -> 0.56 | J28: =ROUNDUP(IFERROR(IF(H28="",J27*I28,H28),""),1) -> 0 | K28: чел. ч | M28: =IFERROR(IF(L28<>"","",VLOOKUP(C28&D28&K28,НН!A:J,10,)),"") -> 1207.8 | N28: =IFERROR(IF(L28="",M28*J28,J28*L28),"") -> 0 | O28: расчет при старом способе:
C30: Нет | D30: Перегородка
C31: Собственное производство | D31: Ручная формовка перегородки | E31: 1 | F31: {=IF(ISBLANK(C31),"",IF(OR(C31=Списки!$AG$15:$AG$17),"нет","да"))} -> нет | I31: 20 | J31: =IF(C30="нет",0,IF(I31="",I31,I31))*E31 -> 0 | K31: кг | M31: =IFERROR(IF(L31<>"","",VLOOKUP(C31&D31&K31,НН!A:J,10,)),"") -> 310.2 | N31: =IFERROR(IF(L31="",M31*J31,J31*L31),"") -> 0
C32: ФОТ | D32: ФОТ | F32: {=IF(ISBLANK(C32),"",IF(OR(C32=Списки!$AG$15:$AG$17),"нет","да"))} -> нет | I32: 1 | J32: =ROUNDUP(IF(H32="",J31*I32,H32),1) -> 0 | K32: чел. ч | M32: =IFERROR(IF(L32<>"","",VLOOKUP(C32&D32&K32,НН!A:J,10,)),"") -> 1207.8 | N32: =IFERROR(IF(L32="",M32*J32,J32*L32),"") -> 0
C33: Собственное производство | D33: Ламинирование перегородки к корпусу | F33: {=IF(ISBLANK(C33),"",IF(OR(C33=Списки!$AG$15:$AG$17),"нет","да"))} -> нет | I33: 1 | J33: =1*J31*3/10 -> 0 | K33: кг | M33: =IFERROR(IF(L33<>"","",VLOOKUP(C33&D33&K33,НН!A:J,10,)),"") -> 310.2 | N33: =IFERROR(IF(L33="",M33*J33,J33*L33),"") -> 0
C34: ФОТ | D34: ФОТ | F34: {=IF(ISBLANK(C34),"",IF(OR(C34=Списки!$AG$15:$AG$17),"нет","да"))} -> нет | I34: 1 | J34: =ROUNDUP(IF(H34="",J33*I34,H34),1) -> 0 | K34: чел. ч | M34: =IFERROR(IF(L34<>"","",VLOOKUP(C34&D34&K34,НН!A:J,10,)),"") -> 1207.8 | N34: =IFERROR(IF(L34="",M34*J34,J34*L34),"") -> 0
D36: Входящий патрубок | E36: =ОЛ_ЕМКОСТИ!E49 -> 400 | F36: =ОЛ_ЕМКОСТИ!E50 -> 1 | G36: шт | H36: ПЭ
C37: Собственное производство | D37: =IF(E36>=200,"Труба СК/НПС-К "&E36+100&"-0,1-2500","Ручная формовка патрубка") -> Труба СК/НПС-К 500-0,1-2500 | E37: =IF(H36="Труба стеклокомпозитная","Муфта-2 СК/НПС-К "&E36+100&"-1","Стеклокомпозитная гильза Ø"&E36+100) -> Стеклокомпозитная гильза Ø500 | F37: {=IF(C37="","",IF(OR(C37=Списки!$AG$15:$AG$17),"нет","да"))} -> нет | J37: =IFERROR(IF(SEARCH("*гильза*",E37)=1,0.5*F36),VLOOKUP(E36+100,'Для расчетов'!$A$36:$F$60,4,)*F36) -> 0.5 | K37: =IFERROR(IF(SEARCH("*труба*",D37)=1,"м"),"кг") -> м | L37: =IFERROR(IF(SEARCH("м",K37)=1,"1,00"),"") -> 1,00 | M37: =IFERROR(IF(L37<>"","",VLOOKUP(C37&D37&K37,НН!A:J,10,)),"") | N37: =IFERROR(IF(L37="",M37*J37,J37*L37),0) -> 0.5
C38: Собственное производство | D38: Придание изделию товарного вида | F38: {=IF(C38="","",IF(OR(C38=Списки!$AG$15:$AG$17),"нет","да"))} -> нет | I38: =($E$36+100)/1300*J37 -> 0.19230769 | J38: =IF(COUNTIF(D37,"*труба*")=1,(E36+100)/1300*J37,0) -> 0.19230769 | K38: чел. ч | M38: =IFERROR(IF(L38<>"","",VLOOKUP(C38&D38&K38,НН!A:J,10,)),"") -> 1207.8 | N38: =IFERROR(IF(L38="",M38*J38,J38*L38),"") -> 232.26923
C39: Собственное производство | D39: Ламинирование патрубка к корпусу | F39: {=IF(C39="","",IF(OR(C39=Списки!$AG$15:$AG$17),"нет","да"))} -> нет | J39: =(VLOOKUP(E36+100,'Для расчетов'!A36:D62,4,0)*3/10)*F36 -> 0.57 | K39: кг | M39: =IFERROR(IF(L39<>"","",VLOOKUP(C39&D39&K39,НН!A:J,10,)),"") -> 310.2 | N39: =IFERROR(IF(L39="",M39*J39,J39*L39),"") -> 176.814
C40: ФОТ | D40: ФОТ | F40: {=IF(C40="","",IF(OR(C40=Списки!$AG$15:$AG$17),"нет","да"))} -> нет | I40: =IF(COUNTIF(D39,"*мех*")=1,0.28,IF(COUNTIF(D39,"*ламин*")=1,1)) -> 1 | J40: =ROUNDUP(IF(OR(ОЛ_КОЛОДЦА!$E$43="",ОЛ_КОЛОДЦА!$E$45=""),0,IF(H40="",IFERROR(J39*I40,""),H40)),1) -> 0.6 | K40: чел. ч | M40: =IFERROR(IF(L40<>"","",VLOOKUP(C40&D40&K40,НН!A:J,10,)),"") -> 1207.8 | N40: =IFERROR(IF(L40="",M40*J40,J40*L40),"") -> 724.68
D42: Выходящий патрубок | E42: =ОЛ_ЕМКОСТИ!I49 -> 300 | F42: =ОЛ_ЕМКОСТИ!I50 -> 2 | G42: шт | H42: ПЭ
C43: Собственное производство | D43: =IF(E42>=200,"Труба СК/НПС-К "&E42+100&"-0,1-2500","Ручная формовка патрубка") -> Труба СК/НПС-К 400-0,1-2500 | E43: =IF(H42="Труба стеклокомпозитная","Муфта-2 СК/НПС-К "&E42+100&"-1","Стеклокомпозитная гильза Ø"&E42+100) -> Стеклокомпозитная гильза Ø400 | F43: {=IF(C43="","",IF(OR(C43=Списки!$AG$15:$AG$17),"нет","да"))} -> нет | J43: =IFERROR(IF(SEARCH("*гильза*",E43)=1,0.5*F42),VLOOKUP(E42+100,'Для расчетов'!$A$36:$F$60,4,)*F42) -> 1 | K43: =IFERROR(IF(SEARCH("*труба*",D43)=1,"м"),"кг") -> м | L43: =IFERROR(IF(SEARCH("м",K43)=1,"1,00"),"") -> 1,00 | M43: =IFERROR(IF(L43<>"","",VLOOKUP(C43&D43&K43,НН!A:J,10,)),"") | N43: =IFERROR(IF(L43="",M43*J43,J43*L43),0) -> 1
C44: Собственное производство | D44: Придание изделию товарного вида | F44: {=IF(C44="","",IF(OR(C44=Списки!$AG$15:$AG$17),"нет","да"))} -> нет | I44: =($E$42+100)/1300*J43 -> 0.30769231 | J44: =IF(COUNTIF(D43,"*труба*")=1,(E42+100)/1300*J43,0) -> 0.30769231 | K44: чел. ч | M44: =IFERROR(IF(L44<>"","",VLOOKUP(C44&D44&K44,НН!A:J,10,)),"") -> 1207.8 | N44: =IFERROR(IF(L44="",M44*J44,J44*L44),"") -> 371.63077
C45: Собственное производство | D45: Ламинирование патрубка к корпусу | F45: {=IF(C45="","",IF(OR(C45=Списки!$AG$15:$AG$17),"нет","да"))} -> нет | J45: =(VLOOKUP(E42+100,'Для расчетов'!A42:D68,4,0)*3/10)*F42 -> 0.66 | K45: кг | M45: =IFERROR(IF(L45<>"","",VLOOKUP(C45&D45&K45,НН!A:J,10,)),"") -> 310.2 | N45: =IFERROR(IF(L45="",M45*J45,J45*L45),"") -> 204.732
...

Sheet для шапки
C1: Габаритная длина рабочей части емкости, L мм | D1: Длина трубы для емкости при вертикальном расположении с шахтой обслуживания, мм | E1: Длина трубы для емкости при вертикальном расположении без шахты обслуживания, мм | F1: Длина трубы для емкости при горизонтальном расположении с шахтой обслуживания, мм | G1: Длина трубы для емкости при горизонтальном расположении без шахты обслуживания, мм | H1: Высота возвышения корпуса емкости/шахты обслуживания над землей, мм | I1: Объем емкости, м3 | J1: D шахты обслуживания, мм | K1: Высота шахты h (до верха рабочей части емкости), мм | L1: Длина (для подставновки в ОЛ)
B2: ВертикальноеПодземнаяДа | C2: =D2 -> 4000 | D2: =IF(AND(ОЛ_ЕМКОСТИ!E19<>"",ОЛ_ЕМКОСТИ!E29<>""),ОЛ_ЕМКОСТИ!E29,IF(ОЛ_ЕМКОСТИ!$E$19="",ОЛ_ЕМКОСТИ!$E$29,IF(AND(ОЛ_ЕМКОСТИ!$E$19<>"",ОЛ_ЕМКОСТИ!$E$29=""),CEILING((4*I2/(PI()*(('Калькулятор ЕМК'!$G$5/1000)^2)))*1000,100)))) -> 4000 | H2: =ОЛ_ЕМКОСТИ!$E$26 -> 300 | I2: =IF(AND(ОЛ_ЕМКОСТИ!E19<>"",ОЛ_ЕМКОСТИ!E29<>""),ОЛ_ЕМКОСТИ!E19,IF(ОЛ_ЕМКОСТИ!$E$19="",ROUNDUP((D2/1000*PI()*(('Калькулятор ЕМК'!$G$5/1000)^2))/4,),ОЛ_ЕМКОСТИ!E19)) -> 100 | J2: =ОЛ_ЕМКОСТИ!$E$40 -> 1200 | K2: =ОЛ_ЕМКОСТИ!$E$41+H2 -> 2300 | L2: =D2 -> 4000
B3: ВертикальноеПодземнаяНет | C3: =E3+H3 -> 4300 | E3: =IF(AND(ОЛ_ЕМКОСТИ!E19<>"",ОЛ_ЕМКОСТИ!E29<>""),ОЛ_ЕМКОСТИ!E29,IF(ОЛ_ЕМКОСТИ!$E$19="",ОЛ_ЕМКОСТИ!$E$29,IF(AND(ОЛ_ЕМКОСТИ!$E$19<>"",ОЛ_ЕМКОСТИ!$E$29=""),CEILING((4*I3/(PI()*(('Калькулятор ЕМК'!$G$5/1000)^2)))*1000,100)))) -> 4000 | H3: =ОЛ_ЕМКОСТИ!$E$26 -> 300 | I3: =IF(AND(ОЛ_ЕМКОСТИ!E19<>"",ОЛ_ЕМКОСТИ!E29<>""),ОЛ_ЕМКОСТИ!E19,IF(ОЛ_ЕМКОСТИ!$E$19=0,ROUNDUP((E3/1000*PI()*(('Калькулятор ЕМК'!$G$5/1000)^2))/4,),ОЛ_ЕМКОСТИ!E19)) -> 100 | J3: 0 | K3: 0 | L3: =C3 -> 4300
B4: ВертикальноеНаземнаяДа | C4: =D4 -> 4000 | D4: =IF(AND(ОЛ_ЕМКОСТИ!E19<>"",ОЛ_ЕМКОСТИ!E29<>""),ОЛ_ЕМКОСТИ!E29,IF(ОЛ_ЕМКОСТИ!$E$19="",ОЛ_ЕМКОСТИ!$E$29,IF(AND(ОЛ_ЕМКОСТИ!$E$19<>"",ОЛ_ЕМКОСТИ!$E$29=""),CEILING((4*I4/(PI()*(('Калькулятор ЕМК'!$G$5/1000)^2)))*1000,100)))) -> 4000 | H4: 0 | I4: =IF(AND(ОЛ_ЕМКОСТИ!E19<>"",ОЛ_ЕМКОСТИ!E29<>""),ОЛ_ЕМКОСТИ!E19,IF(ОЛ_ЕМКОСТИ!$E$19=0,ROUNDUP((D4/1000*PI()*(('Калькулятор ЕМК'!$G$5/1000)^2))/4,),ОЛ_ЕМКОСТИ!E19)) -> 100 | J4: =ОЛ_ЕМКОСТИ!$E$40 -> 1200 | K4: =ОЛ_ЕМКОСТИ!$E$41 -> 2000 | L4: =D4 -> 4000
B5: ВертикальноеНаземнаяНет | C5: =E5 -> 4000 | E5: =IF(AND(ОЛ_ЕМКОСТИ!E19<>"",ОЛ_ЕМКОСТИ!E29<>""),ОЛ_ЕМКОСТИ!E29,IF(ОЛ_ЕМКОСТИ!$E$19="",ОЛ_ЕМКОСТИ!$E$29,IF(AND(ОЛ_ЕМКОСТИ!$E$19<>"",ОЛ_ЕМКОСТИ!$E$29=""),CEILING((4*I4/(PI()*(('Калькулятор ЕМК'!$G$5/1000)^2)))*1000,100)))) -> 4000 | H5: 0 | I5: =IF(AND(ОЛ_ЕМКОСТИ!E19<>"",ОЛ_ЕМКОСТИ!E29<>""),ОЛ_ЕМКОСТИ!E19,IF(ОЛ_ЕМКОСТИ!$E$19=0,ROUNDUP((E5/1000*PI()*(('Калькулятор ЕМК'!$G$5/1000)^2))/4,),ОЛ_ЕМКОСТИ!E19)) -> 100 | J5: 0 | K5: 0 | L5: =E5 -> 4000
B6: ГоризонтальноеПодземнаяДа | C6: =F6 -> 13400 | F6: =IF(AND(ОЛ_ЕМКОСТИ!E19<>"",ОЛ_ЕМКОСТИ!E28<>""),ОЛ_ЕМКОСТИ!E28,IF(ОЛ_ЕМКОСТИ!$E$19="",ОЛ_ЕМКОСТИ!$E$28,IF(AND(ОЛ_ЕМКОСТИ!E19<>"",ОЛ_ЕМКОСТИ!E28=""),CEILING((4*(I6-'Калькулятор ЕМК'!$L$5)/(PI()*(('Калькулятор ЕМК'!$G$5/1000)^2)))*1000,100)))) -> 13400 | H6: =ОЛ_ЕМКОСТИ!$E$26 -> 300 | I6: =IF(AND(ОЛ_ЕМКОСТИ!E19<>"",ОЛ_ЕМКОСТИ!E28<>""),ОЛ_ЕМКОСТИ!E19,IF(ОЛ_ЕМКОСТИ!$E$19=0,ROUNDUP((F6/1000*PI()*(('Калькулятор ЕМК'!$G$5/1000)^2))/4+'Калькулятор ЕМК'!L5,),ОЛ_ЕМКОСТИ!E19)) -> 100 | J6: =ОЛ_ЕМКОСТИ!$E$40 -> 1200 | K6: =ОЛ_ЕМКОСТИ!$E$41+H6 -> 2300 | L6: =F6 -> 13400
B7: ГоризонтальноеПодземнаяНет | C7: =G7 -> 13400 | G7: =IF(AND(ОЛ_ЕМКОСТИ!E19<>"",ОЛ_ЕМКОСТИ!E28<>""),ОЛ_ЕМКОСТИ!E28,IF(ОЛ_ЕМКОСТИ!$E$19="",ОЛ_ЕМКОСТИ!$E$28,CEILING((4*(I7-'Калькулятор ЕМК'!$L$5)/(PI()*(('Калькулятор ЕМК'!$G$5/1000)^2)))*1000,100))) -> 13400 | H7: =ОЛ_ЕМКОСТИ!$E$26 -> 300 | I7: =IF(AND(ОЛ_ЕМКОСТИ!E19<>"",ОЛ_ЕМКОСТИ!E28<>""),ОЛ_ЕМКОСТИ!E19,IF(ОЛ_ЕМКОСТИ!$E$19=0,ROUNDUP((G7/1000*PI()*(('Калькулятор ЕМК'!$G$5/1000)^2))/4+'Калькулятор ЕМК'!L5,),ОЛ_ЕМКОСТИ!E19)) -> 100 | J7: 0 | K7: 0 | L7: =G7 -> 13400
B8: ГоризонтальноеНаземнаяДа | C8: =F8+'Калькулятор ЕМК'!G5/2 -> 14900 | F8: =IF(AND(ОЛ_ЕМКОСТИ!E19<>"",ОЛ_ЕМКОСТИ!E28<>""),ОЛ_ЕМКОСТИ!E28,IF(ОЛ_ЕМКОСТИ!$E$19="",ОЛ_ЕМКОСТИ!$E$28,IF(AND(ОЛ_ЕМКОСТИ!E19<>"",ОЛ_ЕМКОСТИ!E28=""),CEILING((4*(I8-'Калькулятор ЕМК'!$L$5)/(PI()*(('Калькулятор ЕМК'!$G$5/1000)^2)))*1000,100)))) -> 13400 | H8: 0 | I8: =IF(AND(ОЛ_ЕМКОСТИ!E19<>"",ОЛ_ЕМКОСТИ!E28<>""),ОЛ_ЕМКОСТИ!E19,IF(ОЛ_ЕМКОСТИ!$E$19=0,ROUNDUP((F8/1000*PI()*(('Калькулятор ЕМК'!$G$5/1000)^2))/4+'Калькулятор ЕМК'!L5,),ОЛ_ЕМКОСТИ!E19)) -> 100 | J8: =ОЛ_ЕМКОСТИ!$E$40 -> 1200 | K8: =ОЛ_ЕМКОСТИ!$E$41 -> 2000 | L8: =F8 -> 13400
B9: ГоризонтальноеНаземнаяНет | C9: =G9+'Калькулятор ЕМК'!G5/2 -> 14900 | G9: =IF(AND(ОЛ_ЕМКОСТИ!E19<>"",ОЛ_ЕМКОСТИ!E28<>""),ОЛ_ЕМКОСТИ!E28,IF(ОЛ_ЕМКОСТИ!$E$19="",ОЛ_ЕМКОСТИ!$E$28,CEILING((4*(I9-'Калькулятор ЕМК'!$L$5)/(PI()*(('Калькулятор ЕМК'!$G$5/1000)^2)))*1000,100))) -> 13400 | H9: 0 | I9: =IF(AND(ОЛ_ЕМКОСТИ!E19<>"",ОЛ_ЕМКОСТИ!E28<>""),ОЛ_ЕМКОСТИ!E19,IF(ОЛ_ЕМКОСТИ!$E$19=0,ROUNDUP((G9/1000*PI()*(('Калькулятор ЕМК'!$G$5/1000)^2))/4+'Калькулятор ЕМК'!L5,),ОЛ_ЕМКОСТИ!E19)) -> 100 | J9: 0 | K9: 0 | L9: =G9 -> 13400

Sheet ОЛ_НАСОСНАЯ_СТАНЦИЯ
B1: ОБЩЕСТВО С ОГРАНИЧЕННОЙ ОТВЕТСТВЕННОСТЬЮ «НОВЫЕ ТРУБНЫЕ ТЕХНОЛОГИИ» 141320, Московская область, г.о. Сергиево-Посадский, д. Коврово, д. 50, помещ. 2 E-mail: info@ntt.su, тел/факс: +7(499) 949-14-04
C4: ОПРОСНЫЙ ЛИСТ НАСОСНОЙ СТАНЦИИ
C6: *к заявке ООО «НТТ» № | E6: ОЛ/
C7: Тип насосной станции | E7: Канализационная
C8: Назначение ОЛ* | D8: → | E8: Материальный расчет
C9: *(выберите одно или несколько назначений) | D9: →
D10: →
D11: →
C12: *Дата заполнения:
C13: *Заказчик:
C14: Стадия проекта: | E14: проект
C15: Объект:
C16: Регион объекта:
C18: Предполагаемый размер насосной станции*:
C20: *Диаметр DN, мм | E20: 3000
C21: *Давление PN, Мпа | E21: 0.1
C22: *Жесткость SN, Па | E22: 10000
C23: Производство | D23: =IF(C23="Производство","Общий метраж выпуска →","Номер заказа →") -> Общий метраж выпуска →
C24: *Глубина корпуса L (подземная часть) , мм | E24: =P46 -> 11500 | G24: ручной ввод
C25: Высота возвышения корпуса насосной станции над землей, мм | E25: 300 | F25: возвышение люков
C26: Установка под проезжей частью (Да/Нет): | E26: Нет
C27: По ТТ МВК (Да/Нет): | E27: Да
C29: Смола:
C31: Тип смолы | E31: Стандарт
C32: Марка смолы | E32: =VLOOKUP(E31,Списки!$BH$1:$BI$4,2,) -> ИЗО
C33: MAX температура жидкости, оС
C34: Вид стоков | E34: Дождевые
C35: Возможное MAX внутреннее давление, кг/см2
C37: Параметры патрубков:
C39: подводящего трубопровода: | G39: напорного трубопровода:
C40: Материал подводящего трубопровода | E40: ПЭ | G40: Материал напорного трубопровода: | I40: ПЭ | M40: Vэф= | N40: =(E51)/(4*P40*E55) -> 2.0124 | O40: м3 | P40: 5 | Q40: 10 | R40: 20 | S40: пусков в час
C41: *Глубина залегания подводящего трубопровода А, мм. | E41: 9910 | F41: =162.1-152.19 -> 9.91 | G41: *Глубина залегания напорного трубопровода В, мм | I41: 2300 | J41: =162.1-159.8 -> 2.3 | M41: Vмин= | N41: =(E51/2)*P41/60 -> 3.354 | O41: м3 | P41: 5 | Q41: 10 | R41: 20 | S41: поминутная работа
C42: *Номинальный диаметр подводящего трубопровода DА, мм | E42: 400 | G42: *Номинальный диаметр напорного трубопровода DВ, мм | I42: 150 | M42: Vраб= | N42: =N41 -> 3.354 | O42: м3
C43: *Направление подводящего трубопровода, в часах | G43: *Направление напорного трубопровода, в часах
C44: *Количество подводящих трубопроводов, шт. | E44: 1 | G44: *Количество напорных трубопроводов, шт. | I44: 2 | M44: hраб= | N44: =4*N42/(PI()*POWER(E20/1000,2)) -> 0.47449394 | O44: м
